Workbook

Sheet How to use
A1: How this tracker works
A2: Blue columns (Run date → Review?) come from the agent. Don't edit them; update_tracker.py fills them from agent_log.csv after each run.
A3: Orange columns (Your verdict → Notes) are yours. Cream cells are where you type; most have dropdowns.
A5: Weekly routine (~10 minutes)
A6: 1. After the Monday run, get agent_log.csv from the repo and run: python update_tracker.py
A7: 2. Filter Review? to 'Yes' and 'Sample'. Label Your verdict for each, and Agent error when it got something wrong.
A8: 3. Update Applied?, Outcome and Outcome date as things happen.
A10: Why the 'Sample' rows matter
A11: Labeling only approved jobs tells you how good the agent's picks are, never what it throws away. The Sample rows are a stable ~10% of filtered and low-scoring jobs. Your verdicts on them are the only way to measure false negatives, and each labeled row becomes test data when you change the rules.
A13: Example row
A14: Row 2 onward on Agent Log are this week's five recommended jobs, entered by hand because the run log starts with the next run. Their agent columns (score, reason, track) are blank: fill the score in from this week's report if you want them counted.
A16: Test cases
... A20: Add them to Agent Log with Decision = "not surfaced". They count toward your applications but not the agent's precision, and they show what it's missing.

Sheet Agent Log
A1: Run date | B1: Company | C1: Title | D1: Location | E1: Decision | F1: Score | G1: Agent reason | H1: Hiring track | I1: Rules version | J1: URL | K1: Review? | L1: Your verdict | M1: Agent error | N1: Applied? | O1: Date applied | P1: Outcome | Q1: Outcome date | R1: Package issues | S1: Notes
B2: Charles River Associates | C2: Management Advisory Analyst/Associate (Energy) | D2: Boston, MA | E2: not surfaced | K2: Yes | L2: Should apply | M2: None | N2: Yes | O2: 46290 | P2: No response | R2: Posting requires phone + address on resume; generated resume had neither | S2: Found yourself, via the agent's near-miss CRA Finance posting (row 8)
A3: 46290 | B3: IQVIA | C3: MASC | E3: approved | F3: 95 | I3: legacy | K3: Yes | L3: Should apply | M3: None | N3: Yes | O3: 46290 | P3: No response | S3: Also approved 9/23 at 85
A4: 46290 | B4: Hewlett Packard Enterprise | C4: Data Science Graduate | E4: approved | F4: 90 | I4: legacy | K4: Yes | L4: Should apply | M4: None | N4: Yes | O4: 46290 | P4: Screening | Q4: 46290 | S4: Screening quiz done 9/25. Recruiter: Robyn James (robyn.james@hpe.com). Also approved 9/23 (99, then 95).
A5: 46290 | B5: Management Solutions | C5: Data Science Consultant (Class of 2027) | D5: Boston, MA | E5: approved | F5: 85 | I5: legacy | K5: Yes | L5: Should apply | M5: Package problem | N5: Yes | O5: 46290 | P5: No response | R5: 2-page resume; company brief described a different firm; letter said 'LinkedIn' | S5: Seeded by hand; add score from the report
A6: 46290 | B6: Sentinel Group | C6: Business Analyst I | D6: Wakefield, MA | E6: approved | F6: 92 | I6: legacy | K6: Yes | L6: Maybe | M6: Timing mismatch | R6: 2-page resume; filler tails on bullets; 78% stat generalized; brief described a different firm | S6: Likely an immediate hire; Sept 2027 start is a poor fit. Optional. Also approved 9/23 at 86.
A7: 46272 | B7: BCG X | C7: Forward Deployed AI Scientist, Campus, United States | D7: United States | E7: approved | F7: 95 | I7: legacy | J7: https://www.linkedin.com/jobs/view/forward-deployed-ai-scientist-campus-united-states-bcg-x-at-bcg-x-4455452897 | K7: Yes | L7: Should apply | M7: None | N7: Yes | S7: Only application from the first run after relaunch; add date applied and outcome
A8: 46290 | B8: Charles River Associates | C8: (2027 Bachelor's/Master's graduates) Accounting/Business/Finance Consulting Analyst/Associate | E8: near_miss | F8: 80 | I8: legacy | K8: Yes | L8: Should apply | N8: No | S8: Near miss that led you to apply to CRA's Energy role instead. Filtered as an "internship" in both 9/23 runs (LinkedIn metadata).
A9: 46279 | B9: QuantumBlack, AI by McKinsey | C9: Data Scientist | E9: approved | F9: 96 | I9: legacy | K9: Yes | S9: Test case T1
A10: 46280 | B10: Fidelity Investments | C10: Quantitative Analyst | E10: approved | F10: 88 | I10: legacy | K10: Yes
A11: 46282 | B11: Calibrate | C11: Junior Data Analyst | E11: approved | F11: 95 | I11: legacy | J11: https://www.linkedin.com/jobs/view/junior-data-analyst-at-calibrate-4460477929 | K11: Yes | S11: Also approved 9/15 at 95. Test cases T2, T3
A12: 46286 | B12: Jobright.ai | C12: Machine Learning Engineer, Applied AI — New Grad | E12: approved | F12: 95 | I12: legacy | K12: Yes | S12: Closed the same day. Test case T5
A13: 46286 | B13: Jobright.ai | C13: Machine Learning Engineer, New Grad | E13: approved | F13: 95 | I13: legacy | K13: Yes | S13: Same posting as the row above. Test case T5
A14: 46286 | B14: Arrowstreet Capital | C14: Quantitative Researcher | E14: approved | F14: 95 | I14: legacy | K14: Yes | S14: Scored 85 on 9/15. Test case T4
A15: 46288 | B15: Jerry | C15: Associate, BizOps & Analytics | E15: approved | F15: 99 | I15: legacy | K15: Yes | S15: Test case T6
A16: 46288 | B16: GMO | C16: Quantitative Technology Associate - Class of 2027 | E16: approved | F16: 98 | I16: legacy | K16: Yes
A17: 46288 | B17: BRG | C17: Fall 2027 Economic Consulting Associate | E17: approved | F17: 97 | I17: legacy | K17: Yes | S17: Deadline Oct 16 (final review)
A18: 46288 | B18: Charles River Associates | C18: (2027 Bachelor's/Master's graduates) Economics Consulting Analyst/Associate | E18: approved | F18: 96 | I18: legacy | K18: Yes
A19: 46288 | B19: Keystone | C19: Associates and Consultants (2027 Graduates) | E19: approved | F19: 92 | I19: legacy | K19: Yes
A20: 46288 | B20: IBM | C20: Quantum Data Analyst Intern 2027 | E20: filtered | G20: internship role; requires a masters degree | I20: legacy
A21: 46288 | B21: AMD | C21: 2027 Undergrad Data Analyst Intern/co-op | E21: filtered | G21: internship role; start date 2027-01 is before graduation | I21: legacy
A22: 46288 | B22: AMD | C22: 2027 Masters Data Analyst Intern/co-op | E22: filtered | G22: internship role; requires a masters degree; start date 2027-01 is before graduation | I22: legacy
A23: 46288 | B23: Keystone | C23: 2027 Summer Associates and Consultants Interest | E23: filtered | G23: internship role | I23: legacy
A24: 46288 | B24: Keystone | C24: MBA Consultant (2027 Grads) | E24: filtered | G24: requires 5+ years of experience; requires a masters degree | I24: legacy
A25: 46288 | B25: Mapfre | C25: Intern - Advanced Analytics (Summer 2027) | E25: filtered | G25: internship role; requires a masters degree | I25: legacy
A26: 46288 | B26: Capital One | C26: Current Master's - Data Science Internship - Summer 2027 | E26: filtered | G26: internship role; requires a masters degree; requires relocation to Cambridge, MA; targets graduates 2027-09 to 2028-08 | I26: legacy | S26: Test case T9
A27: 46288 | B27: John Hancock | C27: Summer Intern 2027 - AI | E27: filtered | G27: internship role | I27: legacy
A28: 46288 | B28: Capital One | C28: Current PhD - Data Science Internship - Summer 2027 | E28: filtered | G28: internship role; requires a phd degree | I28: legacy
A29: 46288 | B29: Merck | C29: 2027 Future Talent Program - Nonclinical Drug Safety Data Scientist - Intern | E29: filtered | G29: internship role | I29: legacy
A30: 46288 | B30: Wayfair | C30: Machine Learning Science Intern - Summer 2027 | E30: filtered | G30: internship role; requires a phd degree; targets graduates 2027-12 to 2028-08 | I30: legacy
A31: 46288 | B31: Merck | C31: 2027 Future Talent Program - Epidemiology and RWE Capabilities & Analytics - Intern | E31: filtered | G31: internship role; requires a phd degree | I31: legacy
A32: 46288 | B32: Google | C32: Data Scientist, Product Intern, MS, Summer 2027 | E32: filtered | G32: internship role; requires a masters degree; requires relocation to Cambridge, MA | I32: legacy | S32: Test case T9
A33: 46288 | B33: Liberty Mutual Insurance | C33: Solaria Labs Data Science Co-op (January - June 2027) | E33: filtered | G33: internship role; start date 2027-01 is before graduation | I33: legacy
A34: 46288 | B34: Aspen Technology | C34: Data Science Intern - Summer 2027 - Bedford, MA | E34: filtered | G34: internship role; requires 5+ years of experience; requires a masters degree | I34: legacy
A35: 46288 | B35: MKS Inc. | C35: 2027 Spring Data & Analytics Intern (R20783) | E35: filtered | G35: internship role; start date 2027-01 is before graduation | I35: legacy
A36: 46288 | B36: PwC | C36: Deals - Diligence Analytics Intern - Summer 2027 | E36: filtered | G36: internship role; targets graduates 2028-01 to 2028-12 | I36: legacy
A37: 46288 | B37: Altman Solon | C37: 2027 Summer/Winter Data Analyst | E37: filtered | G37: internship role; targets graduates 2027-12 to 2028-05; start date 2027-01 is before graduation | I37: legacy
A38: 46288 | B38: S&P Global | C38: Machine Learning Engineer - Summer Intern 2027 | E38: filtered | G38: internship role; requires relocation to Cambridge, MA | I38: legacy | S38: Test case T9
A39: 46288 | B39: Kensho Technologies | C39: Machine Learning Engineer - Summer Intern 2027 | E39: filtered | G39: internship role | I39: legacy
A40: 46288 | B40: WHOOP | C40: Business Analyst I (Growth Marketing) | E40: approved | F40: 99 | I40: legacy | K40: Yes
...

Sheet Test cases
A1: Case | B1: First seen | C1: Company | D1: Role | E1: What the agent did | F1: Correct behavior | G1: Failure type | H1: Addressed by | I1: Status | J1: Notes
A2: T1 | B2: 46279 | C2: QuantumBlack, AI by McKinsey | D2: Data Scientist | E2: 96/100; graduation fit justified by the search query "2027", not by anything in the posting | F2: Judge timeline only from the posting's own text | G2: Evidence | H2: Every disqualifying field now needs a verified quote from the posting | I2: Fixed in code
A3: T2 | B3: 46280 | C3: Calibrate | D3: Junior Data Analyst | E3: 95/100 approved: 0–2 years, no class year, program, or start date | F3: Flag as a likely immediate hire; not a top match for a Sept 2027 start | G3: Timing | H3: Hiring-track tag labels it, but only filters when the posting says "immediate" | I3: Partly fixed | J3: linkedin.com/jobs/view/junior-data-analyst-at-calibrate-4460477929
A4: T3 | B4: 46282 | C4: Calibrate | D4: Junior Data Analyst | E4: Resurfaced two days after a package had been generated for it | F4: A packaged job never resurfaces | G4: Memory | H4: Not an agent bug: memory_bank.db was wiped on purpose between runs | I4: Not a bug | J4: Wipes are no longer needed: any change to run_everything.py or the config releases old rejections automatically. Wiping also brings packaged jobs back, which adds duplicate rows here.
A5: T4 | B5: 46286 | C5: Arrowstreet Capital | D5: Quantitative Researcher | E5: Scored 85 on 9/15 and 95 on 9/21 for the same posting | F5: An unchanged posting scores within about ±5 | G5: Score drift | H5: Calibration anchors in the grader prompt | I5: Partly fixed
A6: T5 | B6: 46286 | C6: Jobright.ai | D6: Machine Learning Engineer (two postings) | E6: Two identical postings under slightly different titles, both 95/100; the posting said "no longer accepting applications" the same day | F6: One entry per job; a closed posting never reaches the report | G6: Duplicate / closed | H6: Duplicates: compared by description (5-word shingles, 85% match). Closed postings: every reported link is re-opened just before the email. | I6: Fixed in code | J6: "Machine Learning Engineer, Applied AI — New Grad" vs "Machine Learning Engineer, New Grad"
A7: T6 | B7: 46288 | C7: Jerry | D7: Associate, BizOps & Analytics | E7: 99/100 while noting a preference for 1+ years of management consulting | F7: A preferred-experience gap costs points: 85–89 at most | G7: Score inflation | H7: Calibration anchors in the grader prompt | I7: Partly fixed | J7: That run scored 99, 99, 98, 97, 96 and wrote "Hurdles: None" more than once
A8: T7 | B8: 46288 | C8: National Legal Aid & Defender Association | D8: Policy Associate | E8: Approved in both 9/23 runs (90, then 89) | F8: Filtered if the role isn't in Greater Boston | G8: Location | H8: Nothing yet | I8: Open | J8: Verify the posting's location; the organization is based in Washington, DC
A9: T8 | B9: 46288 | C9: Avangrid | D9: 2027 Local Rotational Program: Technology, Digital & Analytics | E9: Filtered: "requires relocation" although Boston is one of the listed sites | F9: Eligible when Boston is among the locations | G9: Location | H9: Quote verification; approved 93 in the next run | I9: Fixed in later run
A10: T9 | B10: 46288 | C10: Capital One / Google / S&P Global | D10: Summer 2027 internships | E10: Reason given: "requires relocation to Cambridge, MA" | F10: Cambridge is commutable; these should be filtered as internships only | G10: Location | H10: Nothing yet | I10: Open | J10: Outcome was right, reason was wrong
A11: T10 | B11: 46288 | C11: MarketOnce | D11: Associate Data Analyst | E11: Reason given: "requires relocation to Denver, CO or Boston, MA" | F11: Not relocation when Boston is an option (3+ years still filters it) | G11: Location | H11: Nothing yet | I11: Open | J11: Outcome was right, reason was wrong
A12: T11 | B12: 46288 | C12: Beghou | D12: Associate Consultant - 2027 Start Date | E12: Filtered: "start date 2027-01 is before graduation" | F12: "2027 Start Date" with no month is not January | G12: Timing | H12: Quote verification; approved 94 in the next run | I12: Fixed in later run
A13: T12 | B13: 46288 | C13: Charles River Associates | D13: (2027 Bachelor's/Master's graduates) Accounting/Business/Finance Consulting Analyst/Associate | E13: Filtered as an internship, based on LinkedIn's "Employment type: Internship" field | F13: A graduate-cohort title outranks board metadata: full-time | G13: Metadata | H13: Reached near-miss (80) on 9/25, so it now passes the rules | I13: Fixed in later run | J13: The Cyber & Forensic Technology posting was filtered the same way; not seen since
A14: T13 | B14: 46288 | C14: Alvarez & Marsal | D14: Associate - Global Transaction Analytics | E14: "Start date immediate", based on "recruits on an ongoing basis... until filled" | F14: Rolling applications are not an immediate start (2+ years still filters it) | G14: Timing | H14: Extraction prompt separates the application process from the start date | I14: Fixed in code
A15: T14 | B15: 46288 | C15: Iron Mountain | D15: Machine Learning Associate | E15: 88/100 approved despite a stated requirement for Golang or Java/Kotlin | F15: An unmet hard technical requirement keeps it below 85 | G15: Unmet requirement | H15: Grader lists unmet required skills with the posting's words; Python verifies the quote, skips anything phrased as preferred, and caps at 79. | I15: Fixed in code
A16: T15 | B16: 46290 | C16: Canonical | D16: Python and Kubernetes Software Engineer - Data, AI/ML & Analytics | E16: 87/100; Kubernetes is in the title and not on the resume | F16: Capped at 79 | G16: Title technology | H16: Title-technology cap, checked in Python | I16: Fixed in code
A17: T16 | B17: 46290 | C17: Mass General Brigham | D17: Business Analyst II | E17: 88/100 approved; a level-II title that prefers 2–4 years | F17: Near miss at most; II/III titles are mid-level | G17: Seniority | H17: Senior ranking covers Senior/Sr/Staff/Principal only | I17: Open
A18: T17 | B18: 46290 | C18: Management Solutions / Sentinel Group | D18: Application packages | E18: Brief about a different company, 2-page resume, flattened 78% stat, filler clauses, "as advertised on LinkedIn" | F18: Correct company, one page, figures kept verbatim, no invented source | G18: Package | H18: One-page fitting, grounding checks, letter rules, brief disambiguation | I18: Fixed in code
A19: T18 | B19: 46272 | C19: (every run) | D19: Email report | E19: PROS/HURDLES bullets collapse into inline " * " text; "Rolling / ASAP. Apply immediately." on nearly every job | F19: Real bullet lists; no urgency the posting doesn't state | G19: Report | H19: Blank lines added around lists, plus a Python pass that inserts them anyway; default deadline is now "No deadline stated". | I19: Fixed in code | J19: Cosmetic

Sheet Summary
B1: Current rules | C1: Legacy runs | E1: Legacy = past runs under older rules: the baseline the current agent should beat.
A2: AGENT OUTPUT | E2: Current-rules rows start with the next run. Rates show — until there are labels.
A3: Jobs in the log | B3: =COUNTIFS('Agent Log'!$I$2:$I$2000,"<>legacy",'Agent Log'!$E$2:$E$2000,"<>not surfaced",'Agent Log'!$B$2:$B$2000,"<>") -> 0 | C3: =COUNTIFS('Agent Log'!$I$2:$I$2000,"legacy") -> 101
A4: Approved (85+) | B4: =COUNTIFS('Agent Log'!$I$2:$I$2000,"<>legacy",'Agent Log'!$E$2:$E$2000,"approved") -> 0 | C4: =COUNTIFS('Agent Log'!$I$2:$I$2000,"legacy",'Agent Log'!$E$2:$E$2000,"approved") -> 31
A5: Near misses | B5: =COUNTIFS('Agent Log'!$I$2:$I$2000,"<>legacy",'Agent Log'!$E$2:$E$2000,"near_miss") -> 0 | C5: =COUNTIFS('Agent Log'!$I$2:$I$2000,"legacy",'Agent Log'!$E$2:$E$2000,"near_miss") -> 1
A6: Scored below floor | B6: =COUNTIFS('Agent Log'!$I$2:$I$2000,"<>legacy",'Agent Log'!$E$2:$E$2000,"below_floor") -> 0 | C6: =COUNTIFS('Agent Log'!$I$2:$I$2000,"legacy",'Agent Log'!$E$2:$E$2000,"below_floor") -> 0
A7: Filtered by rules | B7: =COUNTIFS('Agent Log'!$I$2:$I$2000,"<>legacy",'Agent Log'!$E$2:$E$2000,"filtered") -> 0 | C7: =COUNTIFS('Agent Log'!$I$2:$I$2000,"legacy",'Agent Log'!$E$2:$E$2000,"filtered") -> 69
A9: HOW GOOD ARE ITS PICKS?
A10: Approved jobs you labeled | B10: =COUNTIFS('Agent Log'!$I$2:$I$2000,"<>legacy",'Agent Log'!$E$2:$E$2000,"approved",'Agent Log'!$L$2:$L$2000,"<>") -> 0 | C10: =COUNTIFS('Agent Log'!$I$2:$I$2000,"legacy",'Agent Log'!$E$2:$E$2000,"approved",'Agent Log'!$L$2:$L$2000,"<>") -> 5
A11: …of which you'd apply to | B11: =COUNTIFS('Agent Log'!$I$2:$I$2000,"<>legacy",'Agent Log'!$E$2:$E$2000,"approved",'Agent Log'!$L$2:$L$2000,"Should apply") -> 0 | C11: =COUNTIFS('Agent Log'!$I$2:$I$2000,"legacy",'Agent Log'!$E$2:$E$2000,"approved",'Agent Log'!$L$2:$L$2000,"Should apply") -> 4
A12: Precision | B12: =IFERROR(B11/B10,"—") -> — | C12: =IFERROR(C11/C10,"—") -> 0.8
A13: Near misses you labeled | B13: =COUNTIFS('Agent Log'!$I$2:$I$2000,"<>legacy",'Agent Log'!$E$2:$E$2000,"near_miss",'Agent Log'!$L$2:$L$2000,"<>") -> 0 | C13: =COUNTIFS('Agent Log'!$I$2:$I$2000,"legacy",'Agent Log'!$E$2:$E$2000,"near_miss",'Agent Log'!$L$2:$L$2000,"<>") -> 1
A14: …that should have been approved | B14: =COUNTIFS('Agent Log'!$I$2:$I$2000,"<>legacy",'Agent Log'!$E$2:$E$2000,"near_miss",'Agent Log'!$L$2:$L$2000,"Should apply") -> 0 | C14: =COUNTIFS('Agent Log'!$I$2:$I$2000,"legacy",'Agent Log'!$E$2:$E$2000,"near_miss",'Agent Log'!$L$2:$L$2000,"Should apply") -> 1
A15: Near-miss upgrade rate | B15: =IFERROR(B14/B13,"—") -> — | C15: =IFERROR(C14/C13,"—") -> 1
A17: WHAT IS IT MISSING?
A18: Rejected jobs you labeled | B18: =COUNTIFS('Agent Log'!$I$2:$I$2000,"<>legacy",'Agent Log'!$K$2:$K$2000,"Sample",'Agent Log'!$L$2:$L$2000,"<>") -> 0 | C18: =COUNTIFS('Agent Log'!$I$2:$I$2000,"legacy",'Agent Log'!$E$2:$E$2000,"filtered",'Agent Log'!$L$2:$L$2000,"<>") -> 0
A19: …that you'd actually apply to | B19: =COUNTIFS('Agent Log'!$I$2:$I$2000,"<>legacy",'Agent Log'!$K$2:$K$2000,"Sample",'Agent Log'!$L$2:$L$2000,"Should apply") -> 0 | C19: =COUNTIFS('Agent Log'!$I$2:$I$2000,"legacy",'Agent Log'!$E$2:$E$2000,"filtered",'Agent Log'!$L$2:$L$2000,"Should apply") -> 0
A20: Miss rate | B20: =IFERROR(B19/B18,"—") -> — | C20: =IFERROR(C19/C18,"—") -> —
A21: Jobs you found yourself | B21: =COUNTIF('Agent Log'!$E$2:$E$2000,"not surfaced") -> 1
A23: YOUR APPLICATIONS (all rows)
A24: Applications sent | B24: =COUNTIF('Agent Log'!$N$2:$N$2000,"Yes") -> 5
A25: Reached screening or further | B25: =COUNTIFS('Agent Log'!$N$2:$N$2000,"Yes",'Agent Log'!$P$2:$P$2000,"Screening")+COUNTIFS('Agent Log'!$N$2:$N$2000,"Yes",'Agent Log'!$P$2:$P$2000,"Interview")+COUNTIFS('Agent Log'!$N$2:$N$2000,"Yes",'Agent Log'!$P$2:$P$2000,"Offer") -> 1
A26: Response rate | B26: =IFERROR(B25/B24,"—") -> 0.2
A27: Rejected | B27: =COUNTIFS('Agent Log'!$N$2:$N$2000,"Yes",'Agent Log'!$P$2:$P$2000,"Rejected") -> 0
A29: WHERE THE AGENT GOES WRONG
A30: Score too high | B30: =COUNTIFS('Agent Log'!$I$2:$I$2000,"<>legacy",'Agent Log'!$M$2:$M$2000,"Score too high") -> 0 | C30: =COUNTIFS('Agent Log'!$I$2:$I$2000,"legacy",'Agent Log'!$M$2:$M$2000,"Score too high") -> 0
A31: Score too low | B31: =COUNTIFS('Agent Log'!$I$2:$I$2000,"<>legacy",'Agent Log'!$M$2:$M$2000,"Score too low") -> 0 | C31: =COUNTIFS('Agent Log'!$I$2:$I$2000,"legacy",'Agent Log'!$M$2:$M$2000,"Score too low") -> 0
A32: Wrongly filtered | B32: =COUNTIFS('Agent Log'!$I$2:$I$2000,"<>legacy",'Agent Log'!$M$2:$M$2000,"Wrongly filtered") -> 0 | C32: =COUNTIFS('Agent Log'!$I$2:$I$2000,"legacy",'Agent Log'!$M$2:$M$2000,"Wrongly filtered") -> 0
A33: Should have been filtered | B33: =COUNTIFS('Agent Log'!$I$2:$I$2000,"<>legacy",'Agent Log'!$M$2:$M$2000,"Should have been filtered") -> 0 | C33: =COUNTIFS('Agent Log'!$I$2:$I$2000,"legacy",'Agent Log'!$M$2:$M$2000,"Should have been filtered") -> 0
A34: Timing mismatch | B34: =COUNTIFS('Agent Log'!$I$2:$I$2000,"<>legacy",'Agent Log'!$M$2:$M$2000,"Timing mismatch") -> 0 | C34: =COUNTIFS('Agent Log'!$I$2:$I$2000,"legacy",'Agent Log'!$M$2:$M$2000,"Timing mismatch") -> 1
A35: Location mismatch | B35: =COUNTIFS('Agent Log'!$I$2:$I$2000,"<>legacy",'Agent Log'!$M$2:$M$2000,"Location mismatch") -> 0 | C35: =COUNTIFS('Agent Log'!$I$2:$I$2000,"legacy",'Agent Log'!$M$2:$M$2000,"Location mismatch") -> 0
A36: Package problem | B36: =COUNTIFS('Agent Log'!$I$2:$I$2000,"<>legacy",'Agent Log'!$M$2:$M$2000,"Package problem") -> 0 | C36: =COUNTIFS('Agent Log'!$I$2:$I$2000,"legacy",'Agent Log'!$M$2:$M$2000,"Package problem") -> 1
A38: TEST CASES
A39: Fixed in code | B39: =COUNTIF('Test cases'!$I$2:$I$500,"Fixed in code") -> 7
A40: Fixed in later run | B40: =COUNTIF('Test cases'!$I$2:$I$500,"Fixed in later run") -> 3
A41: Partly fixed | B41: =COUNTIF('Test cases'!$I$2:$I$500,"Partly fixed") -> 3
A42: Open | B42: =COUNTIF('Test cases'!$I$2:$I$500,"Open") -> 4
A43: Needs your call | B43: =COUNTIF('Test cases'!$I$2:$I$500,"Needs your call") -> 0
A44: Not a bug | B44: =COUNTIF('Test cases'!$I$2:$I$500,"Not a bug") -> 1
